<?xml version="1.0"?>
<robot name="tedusar_sensor_head">
    
    <link name="sh_base_link" >
        <visual>
            <geometry>
                <box size="0.03 0.063 0.23"/>
            </geometry>
            <material name="light_gray">
                <color rgba="0.4 0.4 0.4 1.0"/>
            </material>
            <origin rpy="0 0 0" xyz="0 0 0.115"/>
        </visual>
        <collision>
            <geometry>
                <box size="0.03 0.063 0.23"/>
            </geometry>
            <material name="light_gray">
                <color rgba="0.4 0.4 0.4 1.0"/>
            </material>
            <origin rpy="0 0 0" xyz="0 0 0.115"/>
        </collision>
    </link>
    
    <link name="sh_servo1" >
        <visual>
            <geometry>
                <box size="0.042 0.035 0.06"/>
            </geometry>
            <material name="gray">
                <color rgba="0.2 0.2 0.2 1.0"/>
            </material>
            <origin xyz="-0.021 0 0.015" rpy="0 0 0"/>
        </visual>
        <collision>
            <geometry>
                <box size="0.042 0.035 0.06"/>
            </geometry>
            <material name="gray">
                <color rgba="0.2 0.2 0.2 1.0"/>
            </material>
            <origin xyz="-0.021 0 0.015" rpy="0 0 0"/>
        </collision>
    </link>
    
    <link name="sh_servo1_yaw" >
        <visual>
            <geometry>
                <cylinder length="0.02" radius="0.015"/>
            </geometry>
            <material name="light_gray"/>
            <origin rpy="0 -1.570796 0" xyz="0.01 0 0"/>
        </visual>
        <collision>
            <geometry>
                <cylinder length="0.02" radius="0.015"/>
            </geometry>
            <material name="light_gray"/>
            <origin rpy="0 -1.570796 0" xyz="0.01 0 0"/>
        </collision>
    </link>
    
    <link name="sh_servo2" >
        <visual>
            <geometry>
                <box size="0.043 0.035 0.06"/>
            </geometry>
            <material name="gray">
                <color rgba="0.2 0.2 0.2 1.0"/>
            </material>
            <origin xyz="0 0 -0.015" rpy="0 0 0"/>
        </visual>
        <collision>
            <geometry>
                <box size="0.043 0.035 0.06"/>
            </geometry>
            <material name="gray">
                <color rgba="0.2 0.2 0.2 1.0"/>
            </material>
            <origin xyz="0 0 -0.015" rpy="0 0 0"/>
        </collision>
    </link>
    
    <link name="sh_servo2_pitch" >
        <visual>
            <geometry>
                <box size="0.05 0.02 0.04"/>
            </geometry>
            <material name="light_gray"/>
            <origin rpy="0 0 0" xyz="0 0 0.02"/>
        </visual>
        <collision>
            <geometry>
                <box size="0.05 0.02 0.04"/>
            </geometry>
            <material name="light_gray"/>
            <origin rpy="0 0 0" xyz="0 0 0.02"/>
        </collision>
    </link>
    
    
    <link name="sh_platform" >
        <visual>
            <geometry>
                <box size="0.055 0.05 0.007"/>
            </geometry>
            <material name="light_gray"/>
            <origin rpy="0 0 0" xyz="-0.015 0 -0.0035"/>
        </visual>
        <collision>
            <geometry>
                <box size="0.055 0.05 0.007"/>
            </geometry>
            <material name="light_gray"/>
            <origin rpy="0 0 0" xyz="-0.015 0 -0.0035"/>
        </collision>
    </link>
    
    
    <link name="sh_kinect" >
        <visual>
            <geometry>
                <box size="0.06 0.18 0.035"/>
            </geometry>
            <material name="gray"/>
            <origin rpy="0 0 0" xyz="0 0 0"/>
        </visual>
        <collision>
            <geometry>
                <box size="0.06 0.18 0.035"/>
            </geometry>
            <geometry>
                <box size="0.06 0.18 0.035"/>
            </geometry>
            <material name="gray"/>
            <origin rpy="0 0 0" xyz="0 0 0"/>
        </collision>
    </link>
    
    <link name="sh_thermal_camera" >
        <visual>
            <geometry>
                <box size="0.05 0.05 0.05"/>
            </geometry>
            <material name="gray"/>
            <origin rpy="0 0 0" xyz="0 0 0"/>
        </visual>
        <collision>
            <geometry>
                <box size="0.050 0.050 0.05"/>
            </geometry>
            <material name="gray"/>
            <origin rpy="0 0 0" xyz="0 0 0"/>
        </collision>
    </link>
    
    
    <joint name="sh_base_to_servo1" type="fixed">
        <parent link="sh_base_link"/>
        <child link="sh_servo1"/>
        <origin xyz="0 0 0.23" rpy="0 -1.570796 0"/>
    </joint>
    
    <joint name="sh_yaw_joint" type="continuous">
        <parent link="sh_servo1"/>
        <child link="sh_servo1_yaw"/>
        <origin xyz="0 0 0" rpy="0 0 0"/>
    </joint>
    
    <joint name="sh_servo1_yaw_to_servo2" type="fixed">
        <parent link="sh_servo1_yaw"/>
        <child link="sh_servo2"/>
        <origin xyz="0.055 0 0" rpy="-1.570796 0 -1.570796"/>
    </joint>
    
    <joint name="sh_pitch_joint" type="continuous">
        <parent link="sh_servo2"/>
        <child link="sh_servo2_pitch"/>
        <origin xyz="0 0 0" rpy="0 0 0"/>
    </joint>
    
    <joint name="sh_servo2_pitch_to_platform" type="fixed">
        <parent link="sh_servo2_pitch"/>
        <child link="sh_platform"/>
        <origin xyz="0 0 0.045" rpy="0 0 1.570796"/>
    </joint>
    
    <joint name="sh_platform_to_kinect" type="fixed">
        <parent link="sh_platform"/>
        <child link="sh_kinect"/>
        <origin xyz="0 0 0.025" rpy="0 0 0"/>
    </joint>
    
    <joint name="sh_platform_to_thermal_camera" type="fixed">
        <parent link="sh_platform"/>
        <child link="sh_thermal_camera"/>
        <origin xyz="0 0 0.08" rpy="0 0 0"/>
    </joint>
    
</robot>
