<?xml version="1.0" ?>
<!-- =================================================================================== -->
<!-- |    This document was autogenerated by xacro from ../urdf/tedusar_wowbagger.urdf.xacro | -->
<!-- |    EDITING THIS FILE BY HAND IS NOT RECOMMENDED                                 | -->
<!-- =================================================================================== -->
<robot name="tedusar_wowbagger" xmlns:xacro="http://ros.org/wiki/xacro">
  <!--Element Base -->
  <link name="robot_footprint">
	</link>
  <link name="base_link">
    <inertial>
      <mass value="12.0"/>
      <origin xyz="0.0 0.0 0.0"/>
      <inertia ixx="1" ixy="0" ixz="0" iyy="1" iyz="0" izz="1"/>
    </inertial>
    <visual name="base_visual">
      <origin rpy="1.5757105 0 0" xyz="0.1 0.01 0"/>
      <geometry>
        <mesh filename="package://tedusar_mesa_element/meshes/mesa_body.stl" scale="0.001 0.001 0.001"/>
      </geometry>
      <material name="Red">
        <color rgba="1.0 0.0 0.0 1.0"/>
      </material>
    </visual>
    <collision>
      <origin rpy="0 0 0" xyz="0.04 0 0.1"/>
      <geometry>
        <box size="0.70 0.35 0.20"/>
      </geometry>
    </collision>
  </link>
  <joint name="footprint_base_joint" type="fixed">
    <origin rpy="0 0 0" xyz="0 0.0 0.1"/>
    <parent link="robot_footprint"/>
    <child link="base_link"/>
  </joint>
  <link name="left_track_link">
    <inertial>
      <mass value="0.01"/>
      <!-- dummy mass -->
      <origin xyz="0.01 0.01 0.01"/>
      <inertia ixx="1" ixy="0" ixz="0" iyy="1" iyz="0" izz="1"/>
    </inertial>
    <visual name="base_visual">
      <origin rpy="1.5757105 0 0" xyz="0.1 0.01 0"/>
      <geometry>
        <mesh filename="package://tedusar_mesa_element/meshes/mesa_left_track.stl" scale="0.001 0.001 0.001"/>
      </geometry>
      <material name="Black">
        <color rgba="0.0 0.0 0.0 1.0"/>
      </material>
    </visual>
    <collision>
      <origin rpy="0 0 0" xyz="0.03 0.235 0.055"/>
      <geometry>
        <box size="0.75 0.1 0.31"/>
      </geometry>
    </collision>
  </link>
  <joint name="left_track_base_joint" type="fixed">
    <origin rpy="0 0 0" xyz="0 0.0 0.0"/>
    <parent link="base_link"/>
    <child link="left_track_link"/>
  </joint>
  <link name="right_track_link">
    <inertial>
      <mass value="0.01"/>
      <!-- dummy mass -->
      <origin xyz="0.01 0.01 0.01"/>
      <inertia ixx="1" ixy="0" ixz="0" iyy="1" iyz="0" izz="1"/>
    </inertial>
    <visual name="base_visual">
      <origin rpy="1.5757105 0 0" xyz="0.1 0.01 0"/>
      <geometry>
        <mesh filename="package://tedusar_mesa_element/meshes/mesa_right_track.stl" scale="0.001 0.001 0.001"/>
      </geometry>
      <material name="Black">
        <color rgba="0.0 0.0 0.0 1.0"/>
      </material>
    </visual>
    <collision>
      <origin rpy="0 0 0" xyz="0.03 -0.235 0.055"/>
      <geometry>
        <box size="0.75 0.1 0.31"/>
      </geometry>
    </collision>
  </link>
  <joint name="right_track_base_joint" type="fixed">
    <origin rpy="0 0 0" xyz="0 0.0 0.0"/>
    <parent link="base_link"/>
    <child link="right_track_link"/>
  </joint>
  <!--Laser Alignment -->
  <link name="la_base_link">
    <visual>
      <geometry>
        <box size="0.008 0.04 0.15"/>
      </geometry>
      <material name="light_gray">
        <color rgba="0.4 0.4 0.4 1.0"/>
      </material>
      <origin rpy="0 0 0" xyz="0 0 0.08"/>
    </visual>
    <collision>
      <geometry>
        <box size="0.008 0.04 0.15"/>
      </geometry>
      <material name="light_gray">
        <color rgba="0.4 0.4 0.4 1.0"/>
      </material>
      <origin rpy="0 0 0" xyz="0 0 0.08"/>
    </collision>
  </link>
  <link name="la_servo1">
    <visual>
      <geometry>
        <box size="0.035 0.035 0.05"/>
      </geometry>
      <material name="gray">
        <color rgba="0.2 0.2 0.2 1.0"/>
      </material>
      <origin rpy="0 0 0" xyz="-0.0175 0 -0.01"/>
    </visual>
    <collision>
      <geometry>
        <box size="0.035 0.035 0.05"/>
      </geometry>
      <material name="gray">
        <color rgba="0.2 0.2 0.2 1.0"/>
      </material>
      <origin rpy="0 0 0" xyz="-0.0175 0 -0.01"/>
    </collision>
  </link>
  <link name="la_servo1_roll"/>
  <link name="la_servo2">
    <visual>
      <geometry>
        <box size="0.035 0.035 0.05"/>
      </geometry>
      <material name="gray"/>
      <origin rpy="0 0 0" xyz="0 0 -0.02"/>
    </visual>
    <collision>
      <geometry>
        <box size="0.035 0.035 0.05"/>
      </geometry>
      <material name="gray"/>
      <origin rpy="0 0 0" xyz="0 0 -0.02"/>
    </collision>
  </link>
  <link name="la_servo2_pitch">
    <visual>
      <geometry>
        <box size="0.043 0.015 0.045"/>
      </geometry>
      <material name="light_gray"/>
      <origin rpy="0 0 0" xyz="0 0 0.02"/>
    </visual>
    <collision>
      <geometry>
        <box size="0.043 0.015 0.045"/>
      </geometry>
      <material name="light_gray"/>
      <origin rpy="0 0 0" xyz="0 0 0.02"/>
    </collision>
  </link>
  <link name="la_platform">
    <visual>
      <geometry>
        <box size="0.050 0.050 0.005"/>
      </geometry>
      <material name="light_gray"/>
      <origin rpy="0 0 0" xyz="0 0 0.01"/>
    </visual>
    <collision>
      <geometry>
        <box size="0.050 0.050 0.005"/>
      </geometry>
      <material name="light_gray"/>
      <origin rpy="0 0 0" xyz="0 0 0.01"/>
    </collision>
  </link>
  <link name="la_laser">
    <visual>
      <geometry>
        <cylinder length="0.07" radius="0.03"/>
      </geometry>
      <material name="red">
        <color rgba="0.8 0.3 0.2 1.0"/>
      </material>
      <origin rpy="0 0 0" xyz="0 0 0.018"/>
    </visual>
    <collision>
      <geometry>
        <cylinder length="0.07" radius="0.03"/>
      </geometry>
      <material name="red">
        <color rgba="0.8 0.3 0.2 1.0"/>
      </material>
      <origin rpy="0 0 0" xyz="0 0 0.018"/>
    </collision>
  </link>
  <joint name="la_base_to_servo1" type="fixed">
    <parent link="la_base_link"/>
    <child link="la_servo1"/>
    <origin rpy="0 0 0" xyz="0 0 0.135"/>
  </joint>
  <joint name="la_roll_joint" type="continuous">
    <parent link="la_servo1"/>
    <child link="la_servo1_roll"/>
    <origin rpy="0 0 0" xyz="0 0 0"/>
  </joint>
  <joint name="la_servo1_roll_to_servo2" type="fixed">
    <parent link="la_servo1_roll"/>
    <child link="la_servo2"/>
    <origin rpy="0 0 -1.570796" xyz="0.03 0 0.03"/>
  </joint>
  <joint name="la_pitch_joint" type="continuous">
    <parent link="la_servo2"/>
    <child link="la_servo2_pitch"/>
    <origin rpy="0 0 0" xyz="0 0 0"/>
  </joint>
  <joint name="la_servo2_pitch_to_platform" type="fixed">
    <parent link="la_servo2_pitch"/>
    <child link="la_platform"/>
    <origin rpy="0 0 1.570796" xyz="0 0 0.02"/>
  </joint>
  <joint name="la_platform_to_laser" type="fixed">
    <parent link="la_platform"/>
    <child link="la_laser"/>
    <origin rpy="0 0 0" xyz="0 0 0.03"/>
  </joint>
  <joint name="base_to_laser_alignment" type="fixed">
    <parent link="base_link"/>
    <child link="la_base_link"/>
    <origin rpy="0 0 0" xyz="0.30 0 0.19"/>
  </joint>
  <!--Sensor Head -->
  <link name="sh_base_link">
    <visual>
      <geometry>
        <box size="0.03 0.063 0.23"/>
      </geometry>
      <material name="light_gray">
        <color rgba="0.4 0.4 0.4 1.0"/>
      </material>
      <origin rpy="0 0 0" xyz="0 0 0.115"/>
    </visual>
    <collision>
      <geometry>
        <box size="0.03 0.063 0.23"/>
      </geometry>
      <material name="light_gray">
        <color rgba="0.4 0.4 0.4 1.0"/>
      </material>
      <origin rpy="0 0 0" xyz="0 0 0.115"/>
    </collision>
  </link>
  <link name="sh_servo1">
    <visual>
      <geometry>
        <box size="0.042 0.035 0.06"/>
      </geometry>
      <material name="gray">
        <color rgba="0.2 0.2 0.2 1.0"/>
      </material>
      <origin rpy="0 0 0" xyz="-0.021 0 0.015"/>
    </visual>
    <collision>
      <geometry>
        <box size="0.042 0.035 0.06"/>
      </geometry>
      <material name="gray">
        <color rgba="0.2 0.2 0.2 1.0"/>
      </material>
      <origin rpy="0 0 0" xyz="-0.021 0 0.015"/>
    </collision>
  </link>
  <link name="sh_servo1_yaw">
    <visual>
      <geometry>
        <cylinder length="0.02" radius="0.015"/>
      </geometry>
      <material name="light_gray"/>
      <origin rpy="0 -1.570796 0" xyz="0.01 0 0"/>
    </visual>
    <collision>
      <geometry>
        <cylinder length="0.02" radius="0.015"/>
      </geometry>
      <material name="light_gray"/>
      <origin rpy="0 -1.570796 0" xyz="0.01 0 0"/>
    </collision>
  </link>
  <link name="sh_servo2">
    <visual>
      <geometry>
        <box size="0.043 0.035 0.06"/>
      </geometry>
      <material name="gray">
        <color rgba="0.2 0.2 0.2 1.0"/>
      </material>
      <origin rpy="0 0 0" xyz="0 0 -0.015"/>
    </visual>
    <collision>
      <geometry>
        <box size="0.043 0.035 0.06"/>
      </geometry>
      <material name="gray">
        <color rgba="0.2 0.2 0.2 1.0"/>
      </material>
      <origin rpy="0 0 0" xyz="0 0 -0.015"/>
    </collision>
  </link>
  <link name="sh_servo2_pitch">
    <visual>
      <geometry>
        <box size="0.05 0.02 0.04"/>
      </geometry>
      <material name="light_gray"/>
      <origin rpy="0 0 0" xyz="0 0 0.02"/>
    </visual>
    <collision>
      <geometry>
        <box size="0.05 0.02 0.04"/>
      </geometry>
      <material name="light_gray"/>
      <origin rpy="0 0 0" xyz="0 0 0.02"/>
    </collision>
  </link>
  <link name="sh_platform">
    <visual>
      <geometry>
        <box size="0.055 0.05 0.007"/>
      </geometry>
      <material name="light_gray"/>
      <origin rpy="0 0 0" xyz="-0.015 0 -0.0035"/>
    </visual>
    <collision>
      <geometry>
        <box size="0.055 0.05 0.007"/>
      </geometry>
      <material name="light_gray"/>
      <origin rpy="0 0 0" xyz="-0.015 0 -0.0035"/>
    </collision>
  </link>
  <link name="sh_kinect">
    <visual>
      <geometry>
        <box size="0.06 0.18 0.035"/>
      </geometry>
      <material name="gray"/>
      <origin rpy="0 0 0" xyz="0 0 0"/>
    </visual>
    <collision>
      <geometry>
        <box size="0.06 0.18 0.035"/>
      </geometry>
      <geometry>
        <box size="0.06 0.18 0.035"/>
      </geometry>
      <material name="gray"/>
      <origin rpy="0 0 0" xyz="0 0 0"/>
    </collision>
  </link>
  <link name="sh_thermal_camera">
    <visual>
      <geometry>
        <box size="0.05 0.05 0.05"/>
      </geometry>
      <material name="gray"/>
      <origin rpy="0 0 0" xyz="0 0 0"/>
    </visual>
    <collision>
      <geometry>
        <box size="0.050 0.050 0.05"/>
      </geometry>
      <material name="gray"/>
      <origin rpy="0 0 0" xyz="0 0 0"/>
    </collision>
  </link>
  <joint name="sh_base_to_servo1" type="fixed">
    <parent link="sh_base_link"/>
    <child link="sh_servo1"/>
    <origin rpy="0 -1.570796 0" xyz="0 0 0.23"/>
  </joint>
  <joint name="sh_yaw_joint" type="continuous">
    <parent link="sh_servo1"/>
    <child link="sh_servo1_yaw"/>
    <origin rpy="0 0 0" xyz="0 0 0"/>
  </joint>
  <joint name="sh_servo1_yaw_to_servo2" type="fixed">
    <parent link="sh_servo1_yaw"/>
    <child link="sh_servo2"/>
    <origin rpy="-1.570796 0 -1.570796" xyz="0.055 0 0"/>
  </joint>
  <joint name="sh_pitch_joint" type="continuous">
    <parent link="sh_servo2"/>
    <child link="sh_servo2_pitch"/>
    <origin rpy="0 0 0" xyz="0 0 0"/>
  </joint>
  <joint name="sh_servo2_pitch_to_platform" type="fixed">
    <parent link="sh_servo2_pitch"/>
    <child link="sh_platform"/>
    <origin rpy="0 0 1.570796" xyz="0 0 0.045"/>
  </joint>
  <joint name="sh_platform_to_kinect" type="fixed">
    <parent link="sh_platform"/>
    <child link="sh_kinect"/>
    <origin rpy="0 0 0" xyz="0 0 0.025"/>
  </joint>
  <joint name="sh_platform_to_thermal_camera" type="fixed">
    <parent link="sh_platform"/>
    <child link="sh_thermal_camera"/>
    <origin rpy="0 0 0" xyz="0 0 0.08"/>
  </joint>
  <joint name="base_to_sensor_head" type="fixed">
    <parent link="base_link"/>
    <child link="sh_base_link"/>
    <origin rpy="0 0 0" xyz="0.18 0 0.20"/>
  </joint>
</robot>

